Workbook

Sheet Read Me
A1: SHELL & TUBE HX DESIGN — EXCEL PORT OF CIO_Part_1.ipynb
A3: How this workbook is organised
A4: 1. Inputs — every editable number (blue/yellow cells). Nothing else on this sheet is a formula.
A5: 2. Optimizer — the 5 geometry values chosen by the grid-search optimizer (D_shell, D_outer, L_tube, N_passes, N_t). Pre-loaded with the notebook's own result; click Run Optimizer (VBA) to recompute for whatever is on the Inputs sheet.
A6: 3. Rating Engine (Kern) — live formulas, mirrors size_shell_and_tube_cooler(). This is the full Kern check calculation: LMTD/F_T, tube-side Dittus-Boelter, shell-side Kern correlation, U, area, both pressure drops. Recalculates the instant you change an input or the chosen geometry.
A7: 4. Kern Re-Rate — live formulas, mirrors re_rate_exchanger_kern_method(). Standardises onto real tube OD/length and TEMA shell sizes.
A8: 5. NTU Effectiveness — live formulas, mirrors evaluate_tema_exchanger_effectiveness().
A9: 6. VBA Module — read-only listing of the macro source, for reference/audit.
A11: Why VBA only runs the optimizer
A12: Excel has no native nested-loop grid search. Only Stage 1 (the four-level loop over shell diameter, tube OD, pass count and tube length) is implemented in VBA -- a line-for-line translation of optimize_shell_and_tube_cooler(), same bounds, same step sizes. Everything downstream of that (Stages 2-4) is native Excel formulas, not macro code, so the workbook is fully auditable and works even with macros disabled (using the pre-loaded example geometry).
A14: To enable the macro
A15: This ships as a plain .xlsx -- openpyxl (which built this file) cannot author a real embedded VBA project, so a fabricated .xlsm would have a mismatched, Excel-rejected file format. To add the macro: open this .xlsx in Excel, press Alt+F11, right-click VBAProject > Import File, and import ShellTubeOptimizer.bas (included alongside this workbook). Then File > Save As > pick 'Excel Macro-Enabled Workbook (.xlsm)' -- Excel itself now writes a real vbaProject.bin. Then Developer tab > Insert > Button, draw it on the Optimizer sheet, and assign macro RunOptimizer. Or just press Alt+F8 and run RunOptimizer directly, no button needed.
... A23: Dittus-Boelter for tube-side h_i, and Kern's original closed-form shell-side correlation (h_o = 0.36 . Re^0.55 . Pr^(1/3)) for shell-side h_o. Both are established methods.

Sheet Inputs
A1: SHELL & TUBE HEAT EXCHANGER — KERN'S METHOD (Coulson & Richardson Vol.6, Ch.12)
A3: Excel port of CIO_Part_1.ipynb. Blue/yellow cells are editable inputs; everything else is a live formula.
A5: HOT FLUID — SHELL SIDE (MIL-PRF-23699 turbine oil)
A6: Parameter | B6: Value | C6: Units | D6: Notes / Source
A7: Hot fluid inlet temperature, Th_in | B7: 80 | C7: °C | D7: Notebook default
A8: Hot fluid outlet temperature, Th_out | B8: 45 | C8: °C | D8: Notebook default
A9: Hot fluid mass flow rate, m_dot_h | B9: =10000/3600 -> 2.7777778 | C9: kg/s | D9: 10,000 kg/h
A10: Hot fluid density, rho_h | B10: 960.08 | C10: kg/m³ | D10: MIL-PRF-23699 @ bulk T (const. in model)
A11: Hot fluid specific heat, cp_h | B11: 1903.1 | C11: J/kg·K | D11: MIL-PRF-23699
A12: Hot fluid thermal conductivity, k_h | B12: 0.1402 | C12: W/m·K | D12: MIL-PRF-23699
A13: Hot fluid viscosity, mu_h | B13: 0.0116192 | C13: Pa·s | D13: MIL-PRF-23699
A15: COLD FLUID — TUBE SIDE (Water)
A16: Parameter | B16: Value | C16: Units | D16: Notes / Source
A17: Cold fluid inlet temperature, Tc_in | B17: 20 | C17: °C | D17: Notebook default (Cell 1)
A18: Cold fluid outlet temperature, Tc_out | B18: 38 | C18: °C | D18: Notebook default (Cell 1)
A19: Cold fluid specific heat, cp_c | B19: 4183 | C19: J/kg·K | D19: Water
A20: Cold fluid density, rho_c | B20: 985.69 | C20: kg/m³ | D20: Water
A21: Cold fluid viscosity, mu_c | B21: 0.00050362 | C21: Pa·s | D21: Water (503.62e-6)
A22: Cold fluid thermal conductivity, k_c | B22: 0.64601 | C22: W/m·K | D22: Water
A24: MATERIALS / FOULING
A25: Parameter | B25: Value | C25: Units | D25: Notes / Source
A26: Tube wall conductivity, k_wall | B26: 45 | C26: W/m·K | D26: Used by the rating engine (Cell 1)
A27: Inside fouling resistance, R_fi | B27: 0.0001 | C27: m²·K/W
A28: Outside fouling resistance, R_fo | B28: 0.0002 | C28: m²·K/W
A29: Tube roughness | B29: 1.5e-06 | C29: m | D29: Smooth drawn tubing
A31: GEOMETRY RULES
A32: Parameter | B32: Value | C32: Units | D32: Notes / Source
A33: Tube pitch ratio, Pt/Do | B33: 1.25 | C33: – | D33: TEMA triangular pitch
A34: Baffle spacing fraction of shell ID | B34: 0.2 | C34: – | D34: Code names this 'baffle_cut_ratio' but it is really the spacing lB/Ds, not the true TEMA baffle-cut %
A35: Tube wall thickness (search default) | B35: 0.0016 | C35: m | D35: Used while the optimizer searches
A37: OPTIMIZER SEARCH BOUNDS (used by the VBA macro on the 'Optimizer' sheet)
A38: Parameter | B38: Value | C38: Units | D38: Notes / Source
A39: Tube length, min | B39: 2 | C39: m
A40: Tube length, max | B40: 7.5 | C40: m
A41: Tube length step | B41: 0.25 | C41: m
A42: Shell inside diameter, min | B42: 0.2 | C42: m
A43: Shell inside diameter, max | B43: 2.5 | C43: m
A44: Shell inside diameter step | B44: 0.05 | C44: m
A45: Tube outer diameter, min | B45: 0.016 | C45: m
A46: Tube outer diameter, max | B46: 0.05 | C46: m
...

Sheet Optimizer
A1: STAGE 1 — CONSTRAINT-BASED OPTIMIZER (grid search, run via VBA macro)
A3: Click the 'Run Optimizer' button (or Alt+F8 > RunOptimizer) to re-run the exact nested-loop grid search from optimize_shell_and_tube_cooler() in Python, using the bounds on the Inputs sheet. It writes the five geometry cells below, which every other sheet in this workbook reads from live. The values shown now are a pre-loaded example (the notebook's own result) so the rest of the workbook is usable before you ever run the macro.
A6: CHOSEN OPTIMAL DESIGN (macro output — most-compact design meeting all constraints)
A7: Parameter | B7: Value | C7: Units | D7: Notes / Source
A8: Shell inside diameter, D_shell | B8: 0.25 | C8: m | D8: Example result from the Python optimizer
A9: Tube outer diameter, D_outer | B9: 0.034 | C9: m | D9: 34 mm
A10: Tube length, L_tube | B10: 7.5 | C10: m
A11: Number of tube passes, N_passes | B11: 8 | C11: –
A12: Number of tubes, N_t | B12: 32 | C12: –
A14: Optimizer status | B14: Example (pre-loaded) — click Run Optimizer to recompute | D14: Written by the macro
A15: Provided area at optimum (m²) | B15: 25.635 | C15: m² | D15: Informational only, cross-check vs. Rating Engine sheet
A18: [Run Optimizer] <- assign macro RunOptimizer to a Form Control button here (Developer tab > Insert > Button)

Sheet Rating Engine (Kern)
A1: STAGE 2 — RATING ENGINE (live formulas, mirrors size_shell_and_tube_cooler())
A3: Every cell below is a live formula reading from Inputs and Optimizer. Change any input or the chosen geometry and this whole sheet recalculates -- this is the Kern's-method check calculation the optimizer runs internally, made visible.
A5: GEOMETRY (from Optimizer sheet)
A6: Parameter | B6: Value | C6: Units | D6: Notes / Source
A7: Shell inside diameter, D_shell_i | B7: =Optimizer!$B$8 -> 0.25 | C7: m
A8: Tube outer diameter, D_o | B8: =Optimizer!$B$9 -> 0.034 | C8: m
A9: Tube inner diameter, D_i | B9: =Optimizer!$B$9-2*Inputs!$B$35 -> 0.0308 | C9: m | D9: OD - 2 x wall thickness
A10: Tube length, L_tube | B10: =Optimizer!$B$10 -> 7.5 | C10: m
A11: Number of tube passes, N_passes | B11: =Optimizer!$B$11 -> 8 | C11: -
A12: Number of tubes, N_t | B12: =Optimizer!$B$12 -> 32 | C12: -
A14: ENERGY BALANCE
A15: Parameter | B15: Value | C15: Units | D15: Notes / Source
A16: Heat duty, Q | B16: =Inputs!$B$9*Inputs!$B$11*(Inputs!$B$7-Inputs!$B$8) -> 185023.61 | C16: W | D16: m_dot_h . cp_h . (Th_in-Th_out)
A17: Heat duty, Q | B17: ='Rating Engine (Kern)'!$B$16/1000 -> 185.02361 | C17: kW
A18: Cold utility flow, m_dot_c | B18: ='Rating Engine (Kern)'!$B$16/(Inputs!$B$19*(Inputs!$B$18-Inputs!$B$17)) -> 2.4573487 | C18: kg/s
A20: LMTD & MULTI-PASS CORRECTION FACTOR F_T (Cengel Eq.11-18 / C&R Eq.12.8)
A21: Parameter | B21: Value | C21: Units | D21: Notes / Source
A22: dT1 = Th_in - Tc_out | B22: =Inputs!$B$7-Inputs!$B$18 -> 42 | C22: K
A23: dT2 = Th_out - Tc_in | B23: =Inputs!$B$8-Inputs!$B$17 -> 25 | C23: K
A24: Counter-flow LMTD | B24: =IF(ABS('Rating Engine (Kern)'!$B$22-'Rating Engine (Kern)'!$B$23)<0.000001,'Rating Engine (Kern)'!$B$22,IF(OR('Rating Engine (Kern)'!$B$22<=0,'Rating Engine (Kern)'!$B$23<=0),('Rating Engine (Kern)'!$B$22+'Rating Engine (Kern)'!$B$23)/2,('Rating Engine (Kern)'!$B$22-'Rating Engine (Kern)'!$B$23)/LN('Rating Engine (Kern)'!$B$22/'Rating Engine (Kern)'!$B$23))) -> 32.768318 | C24: K | D24: Eq.12.4
A25: delta_Tc = Tc_out - Tc_in | B25: =Inputs!$B$18-Inputs!$B$17 -> 18 | C25: K
A26: delta_Th = Th_in - Th_out | B26: =Inputs!$B$7-Inputs!$B$8 -> 35 | C26: K
A27: Th_in - Tc_in | B27: =Inputs!$B$7-Inputs!$B$17 -> 60 | C27: K
A28: R (capacity ratio) | B28: =IF(ABS('Rating Engine (Kern)'!$B$25)>0.000001,'Rating Engine (Kern)'!$B$26/'Rating Engine (Kern)'!$B$25,1000000) -> 1.9444444 | C28: - | D28: Eq.12.6
A29: P (=S, thermal efficiency) | B29: =IF(ABS('Rating Engine (Kern)'!$B$27)>0.000001,'Rating Engine (Kern)'!$B$25/'Rating Engine (Kern)'!$B$27,0) -> 0.3 | C29: - | D29: Eq.12.7
A30: s = SQRT(R^2+1) | B30: =SQRT('Rating Engine (Kern)'!$B$28^2+1) -> 2.1865187 | C30: -
A31: log_arg_num = 1-P | B31: =1-'Rating Engine (Kern)'!$B$29 -> 0.7 | C31: -
A32: log_arg_den = 1-P.R | B32: =1-'Rating Engine (Kern)'!$B$29*'Rating Engine (Kern)'!$B$28 -> 0.41666667 | C32: -
A33: den_term_num = 2-P(R+1-s) | B33: =2-'Rating Engine (Kern)'!$B$29*('Rating Engine (Kern)'!$B$28+1-'Rating Engine (Kern)'!$B$30) -> 1.7726223 | C33: -
A34: den_term_den = 2-P(R+1+s) | B34: =2-'Rating Engine (Kern)'!$B$29*('Rating Engine (Kern)'!$B$28+1+'Rating Engine (Kern)'!$B$30) -> 0.46071104 | C34: -
A35: num_ft = s.LN(log_arg_num/log_arg_den) | B35: =IF(AND('Rating Engine (Kern)'!$B$31>0,'Rating Engine (Kern)'!$B$32>0,'Rating Engine (Kern)'!$B$33>0,'Rating Engine (Kern)'!$B$34>0),'Rating Engine (Kern)'!$B$30*LN('Rating Engine (Kern)'!$B$31/'Rating Engine (Kern)'!$B$32),0) -> 1.1343524 | C35: -
A36: den_ft = (R-1).LN(den_term_num/den_term_den) | B36: =IF(AND('Rating Engine (Kern)'!$B$31>0,'Rating Engine (Kern)'!$B$32>0,'Rating Engine (Kern)'!$B$33>0,'Rating Engine (Kern)'!$B$34>0),('Rating Engine (Kern)'!$B$28-1)*LN('Rating Engine (Kern)'!$B$33/'Rating Engine (Kern)'!$B$34),1) -> 1.2725862 | C36: -
A37: F_T (temperature correction factor) | B37: =IF(AND('Rating Engine (Kern)'!$B$29>0,'Rating Engine (Kern)'!$B$29<1,'Rating Engine (Kern)'!$B$28>0),IF(ABS('Rating Engine (Kern)'!$B$28-1)<0.000001,1,IF(AND(AND('Rating Engine (Kern)'!$B$31>0,'Rating Engine (Kern)'!$B$32>0,'Rating Engine (Kern)'!$B$33>0,'Rating Engine (Kern)'!$B$34>0),ABS('Rating Engine (Kern)'!$B$36)>0.000000001),'Rating Engine (Kern)'!$B$35/'Rating Engine (Kern)'!$B$36,1)),1) -> 0.89137566 | C37: - | D37: Guarded exactly as in the notebook; clamped below
A38: F_T (clamped to [0,1]) | B38: =IFERROR(IF(OR('Rating Engine (Kern)'!$B$37<0,'Rating Engine (Kern)'!$B$37>1),1,'Rating Engine (Kern)'!$B$37),1) -> 0.89137566 | C38: -
A39: Effective LMTD | B39: ='Rating Engine (Kern)'!$B$38*'Rating Engine (Kern)'!$B$24 -> 29.208881 | C39: K | D39: F_T x LMTD_counterflow
A41: TUBE-SIDE HEAT TRANSFER (Dittus-Boelter, water)
A42: Parameter | B42: Value | C42: Units | D42: Notes / Source
A43: Single-tube flow area | B43: =PI()/4*'Rating Engine (Kern)'!$B$9^2 -> 0.00074506011 | C43: m²
A44: Tubes per pass | B44: =MAX(1,'Rating Engine (Kern)'!$B$12/'Rating Engine (Kern)'!$B$11) -> 4 | C44: -
A45: Tube-side flow area (per pass) | B45: ='Rating Engine (Kern)'!$B$44*'Rating Engine (Kern)'!$B$43 -> 0.0029802405 | C45: m²
...

Sheet Kern Re-Rate
A1: STAGE 3 — KERN RE-RATE TO TEMA STANDARD SIZES (live formulas)
A3: Re-rates the design onto standard tube OD/length using Kern's shell-side correlation and the pass-count-aware bundle-diameter constants (Table 12.4). One formula here (tube-side flow area) was corrected from the source notebook -- see the flagged note below.
A5: BUNDLE-DIAMETER CONSTANTS (C&R Table 12.4, by pitch type & pass count)
A6: Passes | B6: K1 (tri) | C6: n1 (tri) | D6: K1 (sq) | E6: n1 (sq)
A7: 1 | B7: 0.319 | C7: 2.142 | D7: 0.215 | E7: 2.207
A8: 2 | B8: 0.249 | C8: 2.207 | D8: 0.156 | E8: 2.291
A9: 4 | B9: 0.175 | C9: 2.285 | D9: 0.158 | E9: 2.263
A10: 6 | B10: 0.0743 | C10: 2.499 | D10: 0.0402 | E10: 2.617
A11: 8 | B11: 0.0365 | C11: 2.675 | D11: 0.0331 | E11: 2.643
A13: TARGETS FROM RATING ENGINE / OPTIMIZER
A14: Parameter | B14: Value | C14: Units | D14: Notes / Source
A15: Target area (from Rating Engine) | B15: ='Rating Engine (Kern)'!$B$73 -> 25.635396 | C15: m² | D15: Provided Surface Area from Stage 2
A16: Number of tube passes | B16: =Optimizer!$B$11 -> 8 | C16: -
A18: GEOMETRY CONVERSIONS TO SI
A19: Parameter | B19: Value | C19: Units | D19: Notes / Source
A20: Standard tube OD, d_o | B20: =Inputs!$B$53/1000 -> 0.03 | C20: m
A21: Standard length, L | B21: =Inputs!$B$54 -> 6.1 | C21: m
A22: Wall thickness, t_wall | B22: =Inputs!$B$56/1000 -> 0.0016 | C22: m
A23: Standard tube ID, d_i | B23: ='Kern Re-Rate'!$B$20-2*'Kern Re-Rate'!$B$22 -> 0.0268 | C23: m
A25: TUBE COUNT & SURFACE AREA
A26: Parameter | B26: Value | C26: Units | D26: Notes / Source
A27: Area per standard tube | B27: =PI()*'Kern Re-Rate'!$B$20*'Kern Re-Rate'!$B$21 -> 0.57491146 | C27: m²
A28: Number of tubes, n_tubes | B28: =CEILING('Kern Re-Rate'!$B$15/'Kern Re-Rate'!$B$27,1) -> 45 | C28: -
A29: Provided surface area | B29: ='Kern Re-Rate'!$B$28*'Kern Re-Rate'!$B$27 -> 25.871016 | C29: m²
A31: BUNDLE & SHELL DIAMETER (pass-aware K1, n1 -- FIXED from hardcoded 6-pass values)
A32: Parameter | B32: Value | C32: Units | D32: Notes / Source
A33: K1 (looked up by pass count) | B33: =IFERROR(IF(LOWER(Inputs!$B$55)="triangular",INDEX($B$7:$B$11,MATCH('Kern Re-Rate'!$B$16,$A$7:$A$11,0)),INDEX($D$7:$D$11,MATCH('Kern Re-Rate'!$B$16,$A$7:$A$11,0))),IF(LOWER(Inputs!$B$55)="triangular",INDEX($B$7:$B$11,2),INDEX($D$7:$D$11,2))) -> 0.0365 | C33: - | D33: Falls back to the 2-pass row if N_passes isn't 1/2/4/6/8
A34: n1 (looked up by pass count) | B34: =IFERROR(IF(LOWER(Inputs!$B$55)="triangular",INDEX($C$7:$C$11,MATCH('Kern Re-Rate'!$B$16,$A$7:$A$11,0)),INDEX($E$7:$E$11,MATCH('Kern Re-Rate'!$B$16,$A$7:$A$11,0))),IF(LOWER(Inputs!$B$55)="triangular",INDEX($C$7:$C$11,2),INDEX($E$7:$E$11,2))) -> 2.675 | C34: -
A35: Bundle diameter, Db | B35: ='Kern Re-Rate'!$B$20*('Kern Re-Rate'!$B$28/'Kern Re-Rate'!$B$33)^(1/'Kern Re-Rate'!$B$34) -> 0.42914616 | C35: m | D35: Eq.12.3b. Validated vs C&R Example 12.1 (918 tubes/2 pass -> 0.826 m)
A36: Shell-bundle clearance | B36: =Inputs!$B$60 -> 0.038 | C36: m | D36: Fixed stand-in for Fig.12.10 chart
A37: Raw shell diameter | B37: ='Kern Re-Rate'!$B$35+'Kern Re-Rate'!$B$36 -> 0.46714616 | C37: m
A38: Standard shell ID | B38: =CEILING('Kern Re-Rate'!$B$37/0.05,1)*0.05 -> 0.5 | C38: m | D38: Rounded up to nearest 50 mm
A40: TUBE-SIDE (water)
A41: Parameter | B41: Value | C41: Units | D41: Notes / Source
A42: Tube pitch | B42: =Inputs!$B$33*Inputs!$B$53/1000 -> 0.0375 | C42: m
A43: Baffle spacing | B43: =0.4*'Kern Re-Rate'!$B$38 -> 0.2 | C43: m | D43: Notebook Cell 2 default (0.4) differs from Cell 1's search value (0.2) -- kept faithful to source; edit if you want them to match
A44: Tubes per pass | B44: ='Kern Re-Rate'!$B$28/'Kern Re-Rate'!$B$16 -> 5.625 | C44: - | D44: FIX: notebook Cell 2 used N_passes . tube_area (ignoring n_tubes entirely) for the tube-side flow area -- a real bug, ~40% off in the validation case. Corrected here to n_tubes/N_passes, matching Cell 1's own logic.
A45: Tube-side flow area | B45: ='Kern Re-Rate'!$B$44*PI()/4*'Kern Re-Rate'!$B$23^2 -> 0.0031730871 | C45: m²
A46: Tube-side velocity, u_t | B46: ='Rating Engine (Kern)'!$B$18/(Inputs!$B$20*'Kern Re-Rate'!$B$45) -> 0.78567772 | C46: m/s
A47: Tube-side Reynolds number | B47: =Inputs!$B$20*'Kern Re-Rate'!$B$46*'Kern Re-Rate'!$B$23/Inputs!$B$21 -> 41211.328 | C47: -
...

Sheet NTU Effectiveness
A1: STAGE 4 — NTU / EFFECTIVENESS (live formulas, 1 shell pass / even tube passes)
A3: Not covered by C&R Ch.12 itself (the book defers to Vol.1) -- this is the standard 1-shell-pass effectiveness-NTU relation (Incropera), matching the notebook's Cell 3.
A5: CAPACITY RATES
A6: Parameter | B6: Value | C6: Units | D6: Notes / Source
A7: Hot fluid capacity rate, C_h | B7: =Inputs!$B$9*Inputs!$B$11 -> 5286.3889 | C7: W/K
A8: Cold fluid capacity rate, C_c | B8: ='Rating Engine (Kern)'!$B$18*Inputs!$B$19 -> 10279.09 | C8: W/K | D8: m_dot_c carried from Stage 2
A9: Minimum capacity rate, C_min | B9: =MIN('NTU Effectiveness'!$B$7,'NTU Effectiveness'!$B$8) -> 5286.3889 | C9: W/K
A10: Maximum capacity rate, C_max | B10: =MAX('NTU Effectiveness'!$B$7,'NTU Effectiveness'!$B$8) -> 10279.09 | C10: W/K
A11: Capacity ratio, C_r | B11: ='NTU Effectiveness'!$B$9/'NTU Effectiveness'!$B$10 -> 0.51428571 | C11: -
A13: NTU & EFFECTIVENESS
A14: Parameter | B14: Value | C14: Units | D14: Notes / Source
A15: Overall U (from Kern re-rate) | B15: ='Kern Re-Rate'!$B$66 -> 229.64861 | C15: W/m²K
A16: Provided area (from Kern re-rate) | B16: ='Kern Re-Rate'!$B$29 -> 25.871016 | C16: m²
A17: Number of transfer units, NTU | B17: ='NTU Effectiveness'!$B$15*'NTU Effectiveness'!$B$16/'NTU Effectiveness'!$B$9 -> 1.1238755 | C17: -
A18: gamma = SQRT(1+Cr^2) | B18: =SQRT(1+'NTU Effectiveness'!$B$11^2) -> 1.1244954 | C18: -
A19: Exponential term, EXP(-NTU.gamma) | B19: =EXP(-'NTU Effectiveness'!$B$17*'NTU Effectiveness'!$B$18) -> 0.28258024 | C19: -
A20: Predicted effectiveness, epsilon | B20: =IF(ABS(1-'NTU Effectiveness'!$B$19)<0.000000001,1/(1+'NTU Effectiveness'!$B$11),2/(1+'NTU Effectiveness'!$B$11+'NTU Effectiveness'!$B$18*(1+'NTU Effectiveness'!$B$19)/(1-'NTU Effectiveness'!$B$19))) -> 0.56743661 | C20: - | D20: 1-shell-pass / even tube-pass relation
A22: ENERGY CHECK (NOTE: uses the separate NTU-stage Tc_in, per source notebook Cell 3)
A23: Parameter | B23: Value | C23: Units | D23: Notes / Source
A24: Actual heat duty, Q_actual | B24: ='Rating Engine (Kern)'!$B$17 -> 185.02361 | C24: kW | D24: Carried from Stage 2
A25: Actual heat duty, Q_actual | B25: ='NTU Effectiveness'!$B$24*1000 -> 185023.61 | C25: W
A26: Max possible heat transfer, Q_max | B26: ='NTU Effectiveness'!$B$9*(Inputs!$B$7-Inputs!$B$64) -> 290751.39 | C26: W | D26: Uses NTU-stage Tc_in, not the Stage-2 Tc_in -- faithful to the notebook's own inconsistency
A27: Actual operational effectiveness ratio | B27: =IF('NTU Effectiveness'!$B$26>0,'NTU Effectiveness'!$B$25/'NTU Effectiveness'!$B$26,0) -> 0.63636364 | C27: - | D27: Q_actual / Q_max

Sheet VBA Module
A1: REFERENCE LISTING — import ShellTubeOptimizer.bas into the VBA editor rather than retyping this.
A3: Option Explicit
A5: ' ============================================================
A6: ' ShellTubeOptimizer.bas
A7: ' Line-for-line translation of optimize_shell_and_tube_cooler()
A8: ' from CIO_Part_1.ipynb. Reads bounds from the Inputs sheet,
A9: ' writes the winning design to the Optimizer sheet.
A10: ' ============================================================
A12: Private Function MilOilCp() As Double
A13: MilOilCp = 1903.1
A14: End Function
A16: Function LMTD_CF(Th_in As Double, Th_out As Double, Tc_in As Double, Tc_out As Double) As Double
... A238: End Sub
